Workbook
Name \0: #REF!
Name \a: #REF!
Name \b: #REF!
Name \c: #REF!
Name \d: #REF!
Name \e: #REF!
Name \f: #REF!
Name \g: #REF!
Name \h: #REF!
Name \i: #REF!
Name \j: #REF!
Name \k: #REF!
Name \l: #REF!
Name \m: #REF!
Name \n: #REF!
Name \o: #REF!
Name \p: #REF!
Name \R: #REF!
Name \s: #REF!
Name \t: #REF!
Name \W: #REF!
Name \z: #REF!
Name ____________________________________________________________b111121: #REF!
Name ____________________________________________________________Ki1: #REF!
Name ____________________________________________________________Ki2: #REF!
Name ____________________________________________________________MAN1: #REF!
Name ____________________________________________________________PB1: #REF!
Name ____________________________________________________________TB2: #REF!
Name ___________________________________________________________b111121: #REF!
Name ___________________________________________________________Ki1: #REF!
Name ___________________________________________________________Ki2: #REF!
Name ___________________________________________________________MAN1: #REF!
Name ___________________________________________________________PB1: #REF!
Name ___________________________________________________________TB2: #REF!
Name __________________________________________________________b111121: #REF!
Name __________________________________________________________Ki1: #REF!
Name __________________________________________________________Ki2: #REF!
Name __________________________________________________________MAN1: #REF!
Name __________________________________________________________PB1: #REF!
Name __________________________________________________________TB2: #REF!
Name _________________________________________________________b111121: #REF!
Name _________________________________________________________Ki1: #REF!
Name _________________________________________________________Ki2: #REF!
Name _________________________________________________________MAN1: #REF!
Name _________________________________________________________PB1: #REF!
Name _________________________________________________________TB2: #REF!
Name ________________________________________________________b111121: #REF!
Name ________________________________________________________Ki1: #REF!
Name ________________________________________________________Ki2: #REF!
Name ________________________________________________________MAN1: #REF!
Name ________________________________________________________PB1: #REF!
Name ________________________________________________________TB2: #REF!
Name _______________________________________________________b111121: #REF!
Name _______________________________________________________Ki1: #REF!
Name _______________________________________________________Ki2: #REF!
Name _______________________________________________________MAN1: #REF!
Name _______________________________________________________PB1: #REF!
Name _______________________________________________________TB2: #REF!
Name ______________________________________________________b111121: #REF!
Name ______________________________________________________Ki1: #REF!

Sheet Abstract-QS
A1: ABSTRACT
B2: Project Name: | C2: : Residential Apartments-Yelahanka
B3: Package Description : | C3: : Civil works for Retaining wall and STP
B4: Purchase/Work Order No: | C4: : WDIRY0151
B5: Purchase/Work Order Value: | C5: =+F34 -> 50536892
B6: Vendor Name: | C6: : Divyashree Infrastructure Projects Pvt Ltd
B7: RA Bill No. | C7: : RA-01
B8: Date of Invoice : | C8: : 17.12.2025
B9: Invoice Number: | C9: : BCIM/2522/01
A11: Sr. No. | B11: DESCRIPTION | C11: Qty as per Final BOQ | D11: Unit | E11: Rate | F11: Amount | G11: Cum. Qty. Upto Previous Bill | H11: Cum. Amount. Upto Previous Bill | I11: Present Quantity | J11: Present Certified Amount | K11: Cum. Qty. TOTAL Bill | L11: Cum. Amount TOTAL Bill | M11: Quantity Balance | N11: Amount Balance | O11: REMARKS
A12: 01.36.61.01.25.56.95 | B12: Each work excavation by mechanical means using JCB etc in all type of soil including dense weathered rock, soft rock including levelling all leads and lifts for footing,rafts,rc wall foundation,trenches etc including excavation for dressing the edges &levelling .Rate to include stacking or dispose the excavated earth within the site premises and spreading in layers to required level. | C12: 6291.89 | D12: Cum | E12: 375 | F12: =+IFERROR(C12*E12,0) -> 2359458.8 | I12: =Excavation!G12 -> 135.46918 | J12: =I12*E12 -> 50800.943 | K12: =G12+I12 -> 135.46918 | L12: =H12+J12 -> 50800.943 | M12: =C12-K12 -> 6156.4208 | N12: =F12-L12 -> 2308657.8
A13: 01.36.61.01.25.56.96 | B13: Earth Backfilling with bougth out earth in foundations and the area whereever specified with approved good quality filling material in plinths,area development etc, whereever specified in layers of not exceeding 300mm thick including breaking clods,storing,transportation,watering,compacting each layer with vibratory compactor/roller and at unaccessible places with wooden/steel rammers to achieve 90 to 95% proctor density at optimum moisture content , cost shall include conveyance of all materials, labour, machinery etc. complete (mode of measurement - Final consolidated filling area with R.L's only will be consolidated) | C13: 4515.83 | D13: Cum | E13: 180 | F13: =+IFERROR(C13*E13,0) -> 812849.4 | I13: =Backfilling!G13 -> 25.10475 | J13: =I13*E13 -> 4518.855 | K13: =G13+I13 -> 25.10475 | L13: =H13+J13 -> 4518.855 | M13: =C13-K13 -> 4490.7253 | N13: =F13-L13 -> 808330.55
A14: 01.36.61.01.25.56.97 | B14: Providing and layering 100 thk P.C.C 1:3:6 M10 of specified thick whereever specified using Msand, 20mm and downsize metal including base reperation, compaction,levelling all leads and lifts, curing and shuttering if necessary etc., complete -below foundation. | C14: 141.75 | D14: Cum | E14: 5750 | F14: =+IFERROR(C14*E14,0) -> 815062.5 | I14: ='PCC-C'!G22 -> 87.8865 | J14: =I14*E14 -> 505347.38 | K14: =G14+I14 -> 87.8865 | L14: =H14+J14 -> 505347.38 | M14: =C14-K14 -> 53.8635 | N14: =F14-L14 -> 309715.12
A15: 01.36.61.01.25.56.98 | B15: Providing ,batching,mixing,transporting through transit mixers , pumping and laying Reinforced Cement Concrete of specified below using ordinary Portland cement of grade 53 from approved manufacturer , manufactured sand 20 mm and down size coarse aggregate ,necessary admixtures approved by consultants (Admixtures from Fosric / Euclid / Asian paints or equivalent ) including all leads and lifts , pumping using line pump or boom placer , vibrating compaction , scaffolding wherever necessary , curing as directed , excluding cost of shuttering and centering . Retaining wall Raft - M30 | C15: 912.81 | D15: Cum | E15: 7750 | F15: =+IFERROR(C15*E15,0) -> 7074277.5 | I15: ='RW Raft-C'!G16+'STP Raft-C'!G17 -> 263.13185 | J15: =I15*E15 -> 2039271.8 | K15: =G15+I15 -> 263.13185 | L15: =H15+J15 -> 2039271.8 | M15: =C15-K15 -> 649.67815 | N15: =F15-L15 -> 5035005.7
A16: 01.36.61.01.25.56.99 | B16: Concrete for Retaining wall and Columns -M30 | C16: 934.98 | D16: Cum | E16: 7750 | F16: =+IFERROR(C16*E16,0) -> 7246095 | I16: ='STP Wall-C'!G15 -> 4.1325 | J16: =I16*E16 -> 32026.875 | K16: =G16+I16 -> 4.1325 | L16: =H16+J16 -> 32026.875 | M16: =C16-K16 -> 930.8475 | N16: =F16-L16 -> 7214068.1
A17: 01.36.61.01.25.56.100 | B17: Proving , fabricating and erection form work at all levels and places and any profiles whereever needed/specified as per drawing including stiking with19mm plastic coated for slab, bottom of column drop and 12mm thick for balance elements, marine resistant waterproof ply with adjustable steel props of acceptable staging system and with sufficient bracing as approved by consultant. Cost to include designing of proper form work and staging system to suit the requiremen, Submission of design calculation and shop drawings for approval , sealing the joints with heavy duty brown self adhesive tape, aligning to line and levels including M.S ties , PVC Spacer , Proving openings /cutouts / pockets , applying deshuttering chemicals , Deshuttering as approved by the consultant etc. complete at all levels with proper finishing which may require chipping & gringing wherever applicable , doublt/ tripple heights and any profiles. Retaining wall raft Shuttering | C17: 1543.24 | D17: Sqm | E17: 725 | F17: =+IFERROR(C17*E17,0) -> 1118849 | I17: ='RW Raft-S'!G16+'STP Raft-S'!G16 -> 126.9965 | J17: =I17*E17 -> 92072.463 | K17: =G17+I17 -> 126.9965 | L17: =H17+J17 -> 92072.463 | M17: =C17-K17 -> 1416.2435 | N17: =F17-L17 -> 1026776.5
A18: 01.36.61.01.25.56.101 | B18: Retaining walls shuttering | C18: 5760.965 | D18: Sqm | E18: 725 | F18: =+IFERROR(C18*E18,0) -> 4176699.6 | I18: ='STP Wall-S'!G15 -> 32.55 | J18: =I18*E18 -> 23598.75 | K18: =G18+I18 -> 32.55 | L18: =H18+J18 -> 23598.75 | M18: =C18-K18 -> 5728.415 | N18: =F18-L18 -> 4153100.9
A19: 01.36.61.01.25.56.102 | B19: Reinforcement steel Fe 550D for Nailing Works Supply , fabricating & fixing in position reinforcement for RCC work with high yield strength ribbed cold twisted tor steel (HYSD) bar of various diameter and grade of steel at all levels conforming to IS specification including unloading , transporting from yard , decoiling , straightening cutting,bending,hoisting , fabricating and placing in position at all level according to drawings and binding the reinforcement with MS annealed binding wire of double fold of 18 gauge and providing PVC cover blocks , for placing the reinforcement position and for maintaining the cover specified and/or according to relevant IS including dewatering whereever necessary. The rate shall inlcude cost of laps and splices,chair binding wire ,spacers,etc.complete all as per design , specification and drawings with all lead & lift for all materials & labour and as directed , at all heights & locations. | C19: 173.01 | D19: MT | E19: 72500 | F19: =+IFERROR(C19*E19,0) -> 12543225 | I19: ='Steel Abstract'!K15 -> 33.673 | J19: =I19*E19 -> 2441292.5 | K19: =G19+I19 -> 33.673 | L19: =H19+J19 -> 2441292.5 | M19: =C19-K19 -> 139.337 | N19: =F19-L19 -> 10101932
A20: 01.36.61.01.25.56.103 | B20: Waterproofing Works Supply and application of penetron white tank system ,integrated water resistance cell in combination with catalytic effective hydrophobic mechanism for below Basement Retaining wall and Walls for Water Retaining Structures / Swimming Pools & Liftpit etc. The product should be conforming higher compressive strength to class R3 & R4 category. Effective transformation of the concrete structure into the barrier type irrespective of thickness and no requirement of further waterproofing system or system protection & to create durable concrete structure by extending the service life of the structure being resistance to up to 20 bar hydrostatic water head pressure & permeability reduction more than 97% when compared with control concrete as per DIN 1048 Part 5 and ACI 212-3R-10-16, conforming to the Valenta/ Darcy's formula & self healing up to 0.5mm cracks through out the service life of the concrete by dosing @ 0.8% by weight of cement / cementitous materials. The PWTC Admixtures must have the approval from MORTH and IRC for durability factor with CE approval and supplied from a CE approved manufacturing unit and must be capable of reducing chloride diffusion co-efficient by more than 45% as compared to control concrete when tested as per ASTM C1556 .The penetron Whitetank System should be carried out in 3 different necessary stages including post construction treatment as a process of treatment conforming Whtetank system & manufacturer's specificatons as detailed in technical specification,complete Approved make Penetron India. | C20: 918.44 | D20: Cum | E20: 1000 | F20: =+IFERROR(C20*E20,0) -> 918440 | I20: ='Penetron-Admixture'!G27 -> 268.86075 | J20: =I20*E20 -> 268860.75 | K20: =G20+I20 -> 268.86075 | L20: =H20+J20 -> 268860.75 | M20: =C20-K20 -> 649.57925 | N20: =F20-L20 -> 649579.25
A21: 01.36.61.01.25.56.104 | B21: Providing and applying penetron coating shake application which is a barrier type Catalyst Crystaline waterproofing treatment to the footing sides,having speed of penetration of 31cm in 56 days and resistance to 16d bar hydrostatic water head & capable of reducing Permeability of concrete by more than 90% compared with control concrete,when tested as per DIN 1048 (after applying 4cycles of hydrostatic pressure) and permeability co-efficient calculated as per Valentia / Darcy's formula & using Penetron plus @ 1kg /Sqm in single coat,treatment as per the manufacturer's specification and as detailed in technical specification , complete work and methodology approved by Consultants.Approved make Penetron India. | C21: 1023.25 | D21: Sqm | E21: 450 | F21: =+IFERROR(C21*E21,0) -> 460462.5 | I21: =K21-G21 -> 0 | J21: =I21*E21 -> 0 | K21: 0 | L21: =H21+J21 -> 0 | M21: =C21-K21 -> 1023.25 | N21: =F21-L21 -> 460462.5
A22: 01.36.61.01.25.56.107 | B22: Providing waterproofing by surface method INTERALLY by following methods with min.10 years guarantee. The first part consists of application of first layer of micro fibre reinforced polymer modified white cementetious two part waterproof coating after base preparation of cleaning , brushing and removal of flaky materials . Grouting the porous area with cementetious grout,fixing of weep holes,grouting of pipes outlet etc. Applying two coats @750 gms/m2/Coat , the coatings shall be applied at intervals and as per the manufacturer's specifications.Cost to include the treatment of walls up to the full height. Measurement shall be accounted for the full height of the walls treated.(Fosroc/pidilite/Asian paint/MYK Arment / Tremco or Equivalent) The second part consists of waterproofing to internal surfaces by 12mm thk in CM 1:4 for walls with waterproofing admixtures Izonil as per manufacturer's specification and consultants ,approval,curingetc.complete.Cost to include necessary grouting of porous areas,watta at the junction of floor and walls, termination at the ends etc, complete.(Pidilite / Lagreens or equivalent) Floors | C22: 390.94 | D22: Sqm | E22: 800 | F22: =+IFERROR(C22*E22,0) -> 312752 | I22: =K22-G22 -> 0 | J22: =I22*E22 -> 0 | K22: 0 | L22: =H22+J22 -> 0 | M22: =C22-K22 -> 390.94 | N22: =F22-L22 -> 312752
A23: 01.36.61.01.25.56.108 | B23: Walls | C23: 1777.07 | D23: Sqm | E23: 900 | F23: =+IFERROR(C23*E23,0) -> 1599363 | I23: =K23-G23 -> 0 | J23: =I23*E23 -> 0 | K23: 0 | L23: =H23+J23 -> 0 | M23: =C23-K23 -> 1777.07 | N23: =F23-L23 -> 1599363
A24: 01.36.61.01.25.56.109 | B24: Tie rod Hole Treatment Providing and treating of all Tierods considering as part of the entire below ground structure in combination with catalytic effective crystalline hydrophobic mechanism conforming compressive strength to class R3 & R4 category repair mortar by after cleaning the surface by air blower / mechanical mwans before starting application . The material must capable of withstanding Hydrostatic pressure of 16bar & chemical resistance when in continuous exposure for 7 days by using catalytic effective Penetrate mortar & required primer & providing finishing coat at all treated areas. | C24: 17530 | D24: Nos | E24: 75 | F24: =+IFERROR(C24*E24,0) -> 1314750 | I24: =K24-G24 -> 0 | J24: =I24*E24 -> 0 | K24: 0 | L24: =H24+J24 -> 0 | M24: =C24-K24 -> 17530 | N24: =F24-L24 -> 1314750
A25: 01.36.61.01.25.56.110 | B25: Construction joint treatment in retaining wall & joint places of raft and wall, basement collection sumps ,STPS, UG sump, roof top collection & dewatering sump. Providing and installing of construction joints in all the joints of the below ground structures including retaining walls & grade slab in combination with catalytic effective hydrophobic mechanism conforming compressive strength to class R3&R4 category repair mortar at all the construction joints / cold joints of the swimminh pool by creating a "U" groove at all the joints and at junctions of raft slab with the retaining wall s etc., after cleaning the surface by air blower / mechanical means before stating appliccation. The material must be capable of withstanding Hydrostatic pressure of 16bar continuous exposure for 7 days by using Penetrative Mortar & required primer & finishing coat at all the construction joints. | C25: 2075.59 | D25: Rmt | E25: 1000 | F25: =+IFERROR(C25*E25,0) -> 2075590 | I25: =K25-G25 -> 0 | J25: =I25*E25 -> 0 | K25: 0 | L25: =H25+J25 -> 0 | M25: =C25-K25 -> 2075.59 | N25: =F25-L25 -> 2075590
M26: =C26-K26 -> 0 | N26: =F26-L26 -> 0
B27: RMC Price Escalation | J27: ='RMC Basic Price Escalation'!O54 -> 67332.734 | L27: =H27+J27 -> 67332.734 | M27: =C27-K27 -> 0 | N27: =F27-L27 -> -67332.734
B28: Steel Price Escalation | J28: =L28-H28 -> -33673 | L28: =+'Steel Basic Price Escalation'!N42 -> -33673 | M28: =C28-K28 -> 0 | N28: =F28-L28 -> 33673
F29: =+IFERROR(C29*E29,0) -> 0 | K29: 0
B30: Total | F30: =SUM(F12:F29) -> 42827874 | H30: =SUM(H20:H29) -> 0 | J30: =SUM(J12:J29) -> 5491450.1 | L30: =SUM(L12:L29) -> 5491450.1 | N30: =SUM(N12:N29) -> 37336424
B31: CGST+ | C31: 0.09 | F31: =F30*9% -> 3854508.7 | J31: =J30*9% -> 494230.51 | L31: =L30*9% -> 494230.51 | N31: =F31-L31 -> 3360278.2
B32: SGST+ | C32: 0.09 | F32: =F30*9% -> 3854508.7 | J32: =J30*9% -> 494230.51 | L32: =L30*9% -> 494230.51 | N32: =F32-L32 -> 3360278.2
B34: Total Gross Certified | F34: =SUM(F30:F33) -> 50536892 | H34: =SUM(H30) -> 0 | J34: =SUM(J30:J33) -> 6479911.1 | L34: =SUM(L30:L33) -> 6479911.1 | N34: =SUM(N30:N33) -> 44056981
B35: Deductions
B36: Mobilisation advance recovery | F36: =F30*20% -> 8565574.9 | J36: =(L36-H36) -> -1098290 | L36: =-L30*20% -> -1098290 | N36: =F36-L36 -> 9663864.9
B37: Deduct for Retention Money | J37: =(L37-H37) -> -274572.5 | L37: =-L30*5% -> -274572.5
B38: Steel Deductions | J38: =(L38-H38) -> -1803930 | L38: =-'Steel Basic Price Escalation'!P44 -> -1803930
B39: Adhoc Recovery
B40: Total for Deductions | H40: =SUM(H36:H39) -> 0 | J40: =SUM(J36:J39) -> -3176792.5 | L40: =SUM(L36:L39) -> -3176792.5 | N40: =SUM(N36:N39) -> 9663864.9
B42: Total Net Certified | H42: =+H34-H40 -> 0 | J42: =+J34+J40 -> 3303118.6 | L42: =+L34+L40 -> 3303118.6

Sheet Abstarct- Contractor 
A1: ABSTRACT
B2: Project Name: | C2: : Residential Apartments-Yelahanka
B3: Package Description : | C3: : Civil works for Retaining wall and STP
B4: Purchase/Work Order No: | C4: : WDIRY0151
B5: Purchase/Work Order Value: | C5: =+F34 -> 50536892
B6: Vendor Name: | C6: : Divyashree Infrastructure Projects Pvt Ltd
B7: RA Bill No. | C7: : RA-01
B8: Date of Invoice : | C8: : 17.12.2025
B9: Invoice Number: | C9: : BCIM/2522/01
A11: Sr. No. | B11: DESCRIPTION | C11: Qty as per Final BOQ | D11: Unit | E11: Rate | F11: Amount | G11: Cum. Qty. Upto Previous Bill | H11: Cum. Amount. Upto Previous Bill | I11: Present Quantity | J11: Present Certified Amount | K11: Cum. Qty. TOTAL Bill | L11: Cum. Amount TOTAL Bill | M11: Quantity Balance | N11: Amount Balance | O11: REMARKS
A12: 01.36.61.01.25.56.95 | B12: Each work excavation by mechanical means using JCB etc in all type of soil including dense weathered rock, soft rock including levelling all leads and lifts for footing,rafts,rc wall foundation,trenches etc including excavation for dressing the edges &levelling .Rate to include stacking or dispose the excavated earth within the site premises and spreading in layers to required level. | C12: 6291.89 | D12: Cum | E12: 375 | F12: =+IFERROR(C12*E12,0) -> 2359458.8 | I12: =K12-G12 -> 135.46918 | J12: =I12*E12 -> 50800.943 | K12: =+[1]Excavation!G11 -> 135.46918 | L12: =H12+J12 -> 50800.943 | M12: =C12-K12 -> 6156.4208 | N12: =F12-L12 -> 2308657.8
A13: 01.36.61.01.25.56.96 | B13: Earth Backfilling with bougth out earth in foundations and the area whereever specified with approved good quality filling material in plinths,area development etc, whereever specified in layers of not exceeding 300mm thick including breaking clods,storing,transportation,watering,compacting each layer with vibratory compactor/roller and at unaccessible places with wooden/steel rammers to achieve 90 to 95% proctor density at optimum moisture content , cost shall include conveyance of all materials, labour, machinery etc. complete (mode of measurement - Final consolidated filling area with R.L's only will be consolidated) | C13: 4515.83 | D13: Cum | E13: 180 | F13: =+IFERROR(C13*E13,0) -> 812849.4 | I13: =K13-G13 -> 26.826 | J13: =I13*E13 -> 4828.68 | K13: =+[1]Backfilling!G11 -> 26.826 | L13: =H13+J13 -> 4828.68 | M13: =C13-K13 -> 4489.004 | N13: =F13-L13 -> 808020.72
A14: 01.36.61.01.25.56.97 | B14: Providing and layering 100 thk P.C.C 1:3:6 M10 of specified thick whereever specified using Msand, 20mm and downsize metal including base reperation, compaction,levelling all leads and lifts, curing and shuttering if necessary etc., complete -below foundation. | C14: 141.75 | D14: Cum | E14: 5750 | F14: =+IFERROR(C14*E14,0) -> 815062.5 | I14: =K14-G14 -> 89.3096 | J14: =I14*E14 -> 513530.2 | K14: =+'[1]PCC-C'!G20 -> 89.3096 | L14: =H14+J14 -> 513530.2 | M14: =C14-K14 -> 52.4404 | N14: =F14-L14 -> 301532.3
A15: 01.36.61.01.25.56.98 | B15: Providing ,batching,mixing,transporting through transit mixers , pumping and laying Reinforced Cement Concrete of specified below using ordinary Portland cement of grade 53 from approved manufacturer , manufactured sand 20 mm and down size coarse aggregate ,necessary admixtures approved by consultants (Admixtures from Fosric / Euclid / Asian paints or equivalent ) including all leads and lifts , pumping using line pump or boom placer , vibrating compaction , scaffolding wherever necessary , curing as directed , excluding cost of shuttering and centering . Retaining wall Raft - M30 | C15: 912.81 | D15: Cum | E15: 7750 | F15: =+IFERROR(C15*E15,0) -> 7074277.5 | I15: =K15-G15 -> 264.2886 | J15: =I15*E15 -> 2048236.7 | K15: =+'[1]RW Raft-C'!G14+'[1]STP Raft-C'!G15 -> 264.2886 | L15: =H15+J15 -> 2048236.7 | M15: =C15-K15 -> 648.5214 | N15: =F15-L15 -> 5026040.8
A16: 01.36.61.01.25.56.99 | B16: Concrete for Retaining wall and Columns -M30 | C16: 934.98 | D16: Cum | E16: 7750 | F16: =+IFERROR(C16*E16,0) -> 7246095 | I16: =K16-G16 -> 4.1325 | J16: =I16*E16 -> 32026.875 | K16: =+'[1]STP Wall-C'!G13 -> 4.1325 | L16: =H16+J16 -> 32026.875 | M16: =C16-K16 -> 930.8475 | N16: =F16-L16 -> 7214068.1
A17: 01.36.61.01.25.56.100 | B17: Proving , fabricating and erection form work at all levels and places and any profiles whereever needed/specified as per drawing including stiking with19mm plastic coated for slab, bottom of column drop and 12mm thick for balance elements, marine resistant waterproof ply with adjustable steel props of acceptable staging system and with sufficient bracing as approved by consultant. Cost to include designing of proper form work and staging system to suit the requiremen, Submission of design calculation and shop drawings for approval , sealing the joints with heavy duty brown self adhesive tape, aligning to line and levels including M.S ties , PVC Spacer , Proving openings /cutouts / pockets , applying deshuttering chemicals , Deshuttering as approved by the consultant etc. complete at all levels with proper finishing which may require chipping & gringing wherever applicable , doublt/ tripple heights and any profiles. Retaining wall raft Shuttering | C17: 1543.24 | D17: Sqm | E17: 725 | F17: =+IFERROR(C17*E17,0) -> 1118849 | I17: =K17-G17 -> 120.683 | J17: =I17*E17 -> 87495.175 | K17: =+'[1]RW Raft-S'!G14+'[1]STP Raft-S'!G14 -> 120.683 | L17: =H17+J17 -> 87495.175 | M17: =C17-K17 -> 1422.557 | N17: =F17-L17 -> 1031353.8
A18: 01.36.61.01.25.56.101 | B18: Retaining walls shuttering | C18: 5760.965 | D18: Sqm | E18: 725 | F18: =+IFERROR(C18*E18,0) -> 4176699.6 | I18: =K18-G18 -> 32.7 | J18: =I18*E18 -> 23707.5 | K18: =+'[1]STP Wall-S'!G13 -> 32.7 | L18: =H18+J18 -> 23707.5 | M18: =C18-K18 -> 5728.265 | N18: =F18-L18 -> 4152992.1
A19: 01.36.61.01.25.56.102 | B19: Reinforcement steel Fe 550D for Nailing Works Supply , fabricating & fixing in position reinforcement for RCC work with high yield strength ribbed cold twisted tor steel (HYSD) bar of various diameter and grade of steel at all levels conforming to IS specification including unloading , transporting from yard , decoiling , straightening cutting,bending,hoisting , fabricating and placing in position at all level according to drawings and binding the reinforcement with MS annealed binding wire of double fold of 18 gauge and providing PVC cover blocks , for placing the reinforcement position and for maintaining the cover specified and/or according to relevant IS including dewatering whereever necessary. The rate shall inlcude cost of laps and splices,chair binding wire ,spacers,etc.complete all as per design , specification and drawings with all lead & lift for all materials & labour and as directed , at all heights & locations. | C19: 173.01 | D19: MT | E19: 72500 | F19: =+IFERROR(C19*E19,0) -> 12543225 | I19: =K19-G19 -> 33.673 | J19: =I19*E19 -> 2441292.5 | K19: =+'[1]Steel Abstract'!K13 -> 33.673 | L19: =H19+J19 -> 2441292.5 | M19: =C19-K19 -> 139.337 | N19: =F19-L19 -> 10101932
A20: 01.36.61.01.25.56.103 | B20: Waterproofing Works Supply and application of penetron white tank system ,integrated water resistance cell in combination with catalytic effective hydrophobic mechanism for below Basement Retaining wall and Walls for Water Retaining Structures / Swimming Pools & Liftpit etc. The product should be conforming higher compressive strength to class R3 & R4 category. Effective transformation of the concrete structure into the barrier type irrespective of thickness and no requirement of further waterproofing system or system protection & to create durable concrete structure by extending the service life of the structure being resistance to up to 20 bar hydrostatic water head pressure & permeability reduction more than 97% when compared with control concrete as per DIN 1048 Part 5 and ACI 212-3R-10-16, conforming to the Valenta/ Darcy's formula & self healing up to 0.5mm cracks through out the service life of the concrete by dosing @ 0.8% by weight of cement / cementitous materials. The PWTC Admixtures must have the approval from MORTH and IRC for durability factor with CE approval and supplied from a CE approved manufacturing unit and must be capable of reducing chloride diffusion co-efficient by more than 45% as compared to control concrete when tested as per ASTM C1556 .The penetron Whitetank System should be carried out in 3 different necessary stages including post construction treatment as a process of treatment conforming Whtetank system & manufacturer's specificatons as detailed in technical specification,complete Approved make Penetron India. | C20: 918.44 | D20: Cum | E20: 1000 | F20: =+IFERROR(C20*E20,0) -> 918440 | I20: =K20-G20 -> 269.7566 | J20: =I20*E20 -> 269756.6 | K20: =+'[1]Penetron-Admixture'!G25 -> 269.7566 | L20: =H20+J20 -> 269756.6 | M20: =C20-K20 -> 648.6834 | N20: =F20-L20 -> 648683.4
A21: 01.36.61.01.25.56.104 | B21: Providing and applying penetron coating shake application which is a barrier type Catalyst Crystaline waterproofing treatment to the footing sides,having speed of penetration of 31cm in 56 days and resistance to 16d bar hydrostatic water head & capable of reducing Permeability of concrete by more than 90% compared with control concrete,when tested as per DIN 1048 (after applying 4cycles of hydrostatic pressure) and permeability co-efficient calculated as per Valentia / Darcy's formula & using Penetron plus @ 1kg /Sqm in single coat,treatment as per the manufacturer's specification and as detailed in technical specification , complete work and methodology approved by Consultants.Approved make Penetron India. | C21: 1023.25 | D21: Sqm | E21: 450 | F21: =+IFERROR(C21*E21,0) -> 460462.5 | I21: =K21-G21 -> 0 | J21: =I21*E21 -> 0 | K21: 0 | L21: =H21+J21 -> 0 | M21: =C21-K21 -> 1023.25 | N21: =F21-L21 -> 460462.5
A22: 01.36.61.01.25.56.107 | B22: Providing waterproofing by surface method INTERALLY by following methods with min.10 years guarantee. The first part consists of application of first layer of micro fibre reinforced polymer modified white cementetious two part waterproof coating after base preparation of cleaning , brushing and removal of flaky materials . Grouting the porous area with cementetious grout,fixing of weep holes,grouting of pipes outlet etc. Applying two coats @750 gms/m2/Coat , the coatings shall be applied at intervals and as per the manufacturer's specifications.Cost to include the treatment of walls up to the full height. Measurement shall be accounted for the full height of the walls treated.(Fosroc/pidilite/Asian paint/MYK Arment / Tremco or Equivalent) The second part consists of waterproofing to internal surfaces by 12mm thk in CM 1:4 for walls with waterproofing admixtures Izonil as per manufacturer's specification and consultants ,approval,curingetc.complete.Cost to include necessary grouting of porous areas,watta at the junction of floor and walls, termination at the ends etc, complete.(Pidilite / Lagreens or equivalent) Floors | C22: 390.94 | D22: Sqm | E22: 800 | F22: =+IFERROR(C22*E22,0) -> 312752 | I22: =K22-G22 -> 0 | J22: =I22*E22 -> 0 | K22: 0 | L22: =H22+J22 -> 0 | M22: =C22-K22 -> 390.94 | N22: =F22-L22 -> 312752
A23: 01.36.61.01.25.56.108 | B23: Walls | C23: 1777.07 | D23: Sqm | E23: 900 | F23: =+IFERROR(C23*E23,0) -> 1599363 | I23: =K23-G23 -> 0 | J23: =I23*E23 -> 0 | K23: 0 | L23: =H23+J23 -> 0 | M23: =C23-K23 -> 1777.07 | N23: =F23-L23 -> 1599363
A24: 01.36.61.01.25.56.109 | B24: Tie rod Hole Treatment Providing and treating of all Tierods considering as part of the entire below ground structure in combination with catalytic effective crystalline hydrophobic mechanism conforming compressive strength to class R3 & R4 category repair mortar by after cleaning the surface by air blower / mechanical mwans before starting application . The material must capable of withstanding Hydrostatic pressure of 16bar & chemical resistance when in continuous exposure for 7 days by using catalytic effective Penetrate mortar & required primer & providing finishing coat at all treated areas. | C24: 17530 | D24: Nos | E24: 75 | F24: =+IFERROR(C24*E24,0) -> 1314750 | I24: =K24-G24 -> 0 | J24: =I24*E24 -> 0 | K24: 0 | L24: =H24+J24 -> 0 | M24: =C24-K24 -> 17530 | N24: =F24-L24 -> 1314750
A25: 01.36.61.01.25.56.110 | B25: Construction joint treatment in retaining wall & joint places of raft and wall, basement collection sumps ,STPS, UG sump, roof top collection & dewatering sump. Providing and installing of construction joints in all the joints of the below ground structures including retaining walls & grade slab in combination with catalytic effective hydrophobic mechanism conforming compressive strength to class R3&R4 category repair mortar at all the construction joints / cold joints of the swimminh pool by creating a "U" groove at all the joints and at junctions of raft slab with the retaining wall s etc., after cleaning the surface by air blower / mechanical means before stating appliccation. The material must be capable of withstanding Hydrostatic pressure of 16bar continuous exposure for 7 days by using Penetrative Mortar & required primer & finishing coat at all the construction joints. | C25: 2075.59 | D25: Rmt | E25: 1000 | F25: =+IFERROR(C25*E25,0) -> 2075590 | I25: =K25-G25 -> 0 | J25: =I25*E25 -> 0 | K25: 0 | L25: =H25+J25 -> 0 | M25: =C25-K25 -> 2075.59 | N25: =F25-L25 -> 2075590
M26: =C26-K26 -> 0 | N26: =F26-L26 -> 0
B27: RMC Price Escalation | J27: =L27-H27 -> 64402.255 | L27: =+'[1]RMC Basic Price Escalation'!O52 -> 64402.255 | M27: =C27-K27 -> 0 | N27: =F27-L27 -> -64402.255
B28: Steel Price Escalation | J28: =L28-H28 -> -33673 | L28: =+'[1]Steel Basic Price Escalation'!N42 -> -33673 | M28: =C28-K28 -> 0 | N28: =F28-L28 -> 33673
F29: =+IFERROR(C29*E29,0) -> 0 | K29: 0
B30: Total | F30: =SUM(F12:F29) -> 42827874 | H30: =SUM(H20:H29) -> 0 | J30: =SUM(J12:J29) -> 5502404.4 | L30: =SUM(L12:L29) -> 5502404.4 | N30: =SUM(N12:N29) -> 37325470
B31: CGST+ | C31: 0.09 | F31: =F30*9% -> 3854508.7 | J31: =J30*9% -> 495216.39 | L31: =L30*9% -> 495216.39 | N31: =F31-L31 -> 3359292.3
B32: SGST+ | C32: 0.09 | F32: =F30*9% -> 3854508.7 | J32: =J30*9% -> 495216.39 | L32: =L30*9% -> 495216.39 | N32: =F32-L32 -> 3359292.3
B34: Total Gross Certified | F34: =SUM(F30:F33) -> 50536892 | H34: =SUM(H30) -> 0 | J34: =SUM(J30:J33) -> 6492837.2 | L34: =SUM(L30:L33) -> 6492837.2 | N34: =SUM(N30:N33) -> 44044054
B35: Deductions
B36: Mobilisation advance recovery | F36: =F30*20% -> 8565574.9 | J36: =L36-H36 -> 1100480.9 | L36: =L30*20% -> 1100480.9 | N36: =F36-L36 -> 7465094
B37: Deduct for Retention Money | J37: =L37-H37 -> 275120.22 | L37: =L30*5% -> 275120.22
B38: Steel Deductions | J38: =L38-H38 -> 1803930 | L38: =+'[1]Steel Basic Price Escalation'!P44 -> 1803930
B39: Adhoc Recovery
B40: Total for Deductions | H40: =SUM(H36:H39) -> 0 | J40: =SUM(J36:J39) -> 3179531.1 | L40: =SUM(L36:L39) -> 3179531.1 | N40: =SUM(N36:N39) -> 7465094
B42: Total Net Certified | H42: =+H34-H40 -> 0 | J42: =+J34-J40 -> 3313306.1 | L42: =+L34-L40 -> 3313306.1
B44: Total Adhoc Certified (70%)

Sheet Excavation
A1: PROJECT : TECHRIDGE- P3
A2: M/s. Divyashree Infrastructure Projects Pvt Ltd
A3: Subject: Excavation Joint Measurement Details
A5: Sl No | B5: Description | C5: Nos | D5: L | E5: B | F5: D | G5: Qty In Cum | H5: Pour card No | I5: Pour Card Date | J5: RA No. | K5: Bottom Lvl | L5: Top Lvl | M5: Depth
B6: Excavation
A7: 1 | B7: West Retaining Wall Raft | C7: 1 | D7: 48.4 | E7: =2.95+0.45+0.45 -> 3.85 | F7: =+M7 -> 0.727 | G7: =+PRODUCT(C7:F7) -> 135.46918 | K7: 95.693 | L7: 96.42 | M7: =+L7-K7 -> 0.727
F8: =+M8 -> 0 | G8: =+PRODUCT(C8:F8) -> 0 | M8: =+L8-K8 -> 0
C10: Cumulative Quantity | G10: =SUM(G2:G9) -> 135.46918
C11: Prev. Billed Quantity | G11: =+'Abstract-QS'!G7 -> 0
C12: Present Bill Quantity | G12: =G10-G11 -> 135.46918

Sheet Backfilling
A1: PROJECT : TECHRIDGE- P3
A2: M/s. Divyashree Infrastructure Projects Pvt Ltd
A3: Subject: Backfilling Joint Measurement Details
A5: Sl No | B5: Description | C5: Nos | D5: L | E5: B | F5: D | G5: Qty In Cum | H5: Pour card No | I5: Pour Card Date | J5: RA No. | K5: Bottom Lvl | L5: Top Lvl | M5: Depth
B6: Backfilling
A7: 1 | B7: Pump Room | C7: 1 | D7: 10.9 | E7: 8 | F7: =+M7 -> 0.255 | G7: =+PRODUCT(C7:F7) -> 22.236 | K7: 92.345 | L7: 92.6 | M7: =+L7-K7 -> 0.255
A8: 2 | B8: Drain pit | C8: 1 | D8: 4.5 | E8: 2.5 | F8: =+M8 -> 0.255 | G8: =+PRODUCT(C8:F8) -> 2.86875 | K8: 92.345 | L8: 92.6 | M8: =+L8-K8 -> 0.255
F9: =+M9 -> 0 | G9: =+PRODUCT(C9:F9) -> 0 | M9: =+L9-K9 -> 0
C11: Cumulative Quantity | G11: =SUM(G2:G10) -> 25.10475
C12: Prev. Billed Quantity | G12: =+'Abstract-QS'!G7 -> 0
C13: Present Bill Quantity | G13: =G11-G12 -> 25.10475

Sheet PCC-C
A1: PROJECT : TECHRIDGE- P3 | B1: : The Quiet Side
A2: M/s. Divyashree Infrastructure Projects Pvt Ltd
A3: Subject: PCC-Concrete Joint Measurement Details
A4: ='Abstract-QS'!C7 -> : RA-01
A5: Sl No | B5: Description | C5: Nos | D5: L | E5: B | F5: D | G5: Qty in Cum | H5: Pour card No | I5: Pour Card Date | J5: RA No. | K5: PCC Top Avg.Level | L5: PCC Bottom Avg. Level | M5: PCC Depth
B7: M10-GRADE
B8: Tower Footings
A9: 1 | B9: West Retaining wall | C9: 1 | D9: 48.4 | E9: 3.15 | F9: =+M9 -> 0.075 | G9: =+PRODUCT(C9:F9) -> 11.4345 | H9: PCC-01 | I9: 45971 | J9: RA-01 | K9: 95.875 | L9: 95.8 | M9: =+K9-L9 -> 0.075
A10: 2 | B10: West Retaining wall | C10: 0 | D10: 48.4 | E10: 3.3 | F10: =+M10 -> 0.005 | G10: =+PRODUCT(C10:F10) -> 0 | H10: PCC-01 | I10: 45971 | J10: RA-01 | K10: 95.88 | L10: 95.875 | M10: =+K10-L10 -> 0.005
A11: 3 | B11: North Retaining Wall | C11: 1 | D11: 8.5 | E11: 3.1 | F11: =+M11 -> 0.075 | G11: =+PRODUCT(C11:F11) -> 1.97625 | H11: PCC-03 | I11: 45987 | J11: RA-01 | K11: 95.875 | L11: 95.8 | M11: =+K11-L11 -> 0.075
B13: STP
A14: 4 | B14: STP | C14: 1 | D14: 530.16 | F14: =+M14 -> 0.1 | G14: =+PRODUCT(C14:F14) -> 53.016 | H14: PCC-02 | I14: 45982 | J14: RA-01 | K14: 92.4 | L14: 92.3 | M14: =+K14-L14 -> 0.1
A15: 5 | B15: STP West Side - Plum Concrete | C15: 1 | D15: 8.4 | E15: 1.2 | F15: 0.5 | G15: =+PRODUCT(C15:F15) -> 5.04 | H15: PCC-04 | I15: 46003 | J15: RA-01 | M15: =+K15-L15 -> 0
A16: 6 | B16: STP West Side - Plum Concrete | C16: 1 | D16: 8.2 | E16: 1.1 | F16: 0.2 | G16: =+PRODUCT(C16:F16) -> 1.804 | H16: PCC-04 | I16: 46003 | J16: RA-01 | M16: =+K16-L16 -> 0
A17: 7 | B17: STP West Side - Plum Concrete | C17: 1 | D17: 16.15 | E17: 1.81 | F17: 0.5 | G17: =+PRODUCT(C17:F17) -> 14.61575 | H17: PCC-04 | I17: 46003 | J17: RA-01 | M17: =+K17-L17 -> 0
A18: 8 | C18: 1 | F18: =+M18 -> 0 | G18: =+PRODUCT(C18:F18) -> 0 | J18: RA-01 | M18: =+K18-L18 -> 0
A19: 9 | C19: 1 | F19: =+M19 -> 0 | G19: =+PRODUCT(C19:F19) -> 0 | J19: RA-01 | M19: =+K19-L19 -> 0
C20: Cumulative Quantity | G20: =SUM(G9:G19) -> 87.8865
C21: Prev. Billed Quantity | G21: =+'Abstract-QS'!G14 -> 0
C22: Present Bill Quantity | G22: =G20-G21 -> 87.8865

Sheet RW Raft-C
A1: PROJECT : TECHRIDGE- P3 | B1: : The Quiet Side
A2: M/s. Divyashree Infrastructure Projects Pvt Ltd
A3: Subject: Retaining Wall Raft Concrete Joint Measurement Details
A4: ='Abstract-QS'!C7 -> : RA-01
A5: Sl No | B5: Description | C5: Nos | D5: L | E5: B | F5: D | G5: Qty in Cum | H5: Grid | I5: Pourcard No | J5: Pourcard Date | K5: RA No. | L5: Raft Bottom Level | M5: Raft Top Level | N5: Depth
B6: RW Raft
A7: 1 | B7: West Retaining wall Raft | C7: 1 | D7: 18.3 | E7: 2.95 | F7: =N7 -> 0.7 | G7: =+PRODUCT(C7:F7) -> 37.7895 | J7: 45989 | K7: RA-01 | L7: 95.875 | M7: 96.575 | N7: =M7-L7 -> 0.7
A8: 2 | B8: West Retaining wall Raft | C8: 1 | D8: 18.3 | E8: 2.95 | F8: =N8 -> 0.03 | G8: =+PRODUCT(C8:F8) -> 1.61955 | J8: 45989 | K8: RA-01 | L8: =M8-0.03 -> 95.85 | M8: 95.88 | N8: =M8-L8 -> 0.03
A9: 3 | B9: West Retaining wall Raft | C9: 1 | D9: 24.8 | E9: 2.95 | F9: =N9 -> 0.7 | G9: =+PRODUCT(C9:F9) -> 51.212 | J9: 45993 | K9: RA-01 | L9: 95.875 | M9: 96.575 | N9: =M9-L9 -> 0.7
A10: 4 | B10: West Retaining wall Raft | C10: 1 | D10: 24.8 | E10: 2.95 | F10: =N10 -> 0.03 | G10: =+PRODUCT(C10:F10) -> 2.1948 | J10: 45993 | K10: RA-01 | L10: =M10-0.03 -> 95.85 | M10: 95.88 | N10: =M10-L10 -> 0.03
G11: =+PRODUCT(C11:F11) -> 0
G12: =+PRODUCT(C12:F12) -> 0
C14: Cumulative Quantity | G14: =SUM(G7:G11) -> 92.81585 | H14: Cum
C15: Prev. Billed Quantity | G15: =+'Abstract-QS'!G15 -> 0 | H15: Cum
C16: Present Bill Quantity | G16: =G14-G15 -> 92.81585 | H16: Cum

Sheet RW Raft-S
A1: PROJECT : TECHRIDGE- P3 | B1: : The Quiet Side
A2: M/s. Divyashree Infrastructure Projects Pvt Ltd
A3: Subject: Retaining Wall Raft SHuttering Joint Measurement Details
A4: ='Abstract-QS'!C7 -> : RA-01
A5: Sl No | B5: Description | C5: Nos | D5: L | E5: B | F5: D | G5: Qty in Sqm | H5: Grid | I5: Pourcard No | J5: Pourcard Date | K5: RA No. | L5: Raft Bottom Level | M5: Raft Top Level | N5: Depth
B6: RW Raft
A7: 1 | B7: West Retaining wall Raft | C7: 1 | D7: 18.3 | E7: 2.95 | F7: =M7-L7 -> 0.7 | G7: =(D7+E7+D7+E7)*F7 -> 29.75 | J7: 45989 | K7: RA-01 | L7: 95.875 | M7: 96.575 | N7: =M7-L7 -> 0.7
A8: 2 | B8: West Retaining wall Raft | C8: 1 | D8: 18.3 | E8: 2.95 | F8: =M8-L8 -> 0.03 | G8: =C8*(D8+E8+D8+E8)*F8 -> 1.275 | J8: 45989 | K8: RA-01 | L8: =M8-0.03 -> 95.85 | M8: 95.88 | N8: =M8-L8 -> 0.03
A9: 3 | B9: West Retaining wall Raft | C9: 1 | D9: 24.8 | E9: 2.95 | F9: =M9-L9 -> 0.7 | G9: =(D9+E9+D9+E9)*F9 -> 38.85 | J9: 45993 | K9: RA-01 | L9: 95.875 | M9: 96.575 | N9: =M9-L9 -> 0.7
A10: 4 | B10: West Retaining wall Raft | C10: 1 | D10: 24.8 | E10: 2.95 | F10: =M10-L10 -> 0.03 | G10: =C10*(D10+E10+D10+E10)*F10 -> 1.665 | J10: 45993 | K10: RA-01 | L10: =M10-0.03 -> 95.85 | M10: 95.88 | N10: =M10-L10 -> 0.03
G11: =+PRODUCT(C11:F11) -> 0
C14: Cumulative Quantity | G14: =SUM(G7:G11) -> 71.54 | H14: Sqm
C15: Prev. Billed Quantity | G15: =+'Abstract-QS'!G17 -> 0 | H15: Sqm
C16: Present Bill Quantity | G16: =G14-G15 -> 71.54 | H16: Sqm

Sheet STP Raft-C
A1: PROJECT : TECHRIDGE- P3 | B1: : The Quiet Side
A2: M/s. Divyashree Infrastructure Projects Pvt Ltd
A3: Subject: STP Raft Concrete Joint Measurement Details
A4: ='Abstract-QS'!C7 -> : RA-01
A5: Sl No | B5: Description | C5: Nos | D5: L | E5: B | F5: D | G5: Qty in Cum | H5: Grid | I5: Pourcard No | J5: Pourcard Date | K5: RA No. | L5: Raft Bottom Level | M5: Raft Top Level | N5: Depth
B6: STP
A7: 1 | B7: STP Raft | C7: 1 | D7: 382.008 | F7: =+N7 -> 0.5 | G7: =+PRODUCT(C7:F7) -> 191.004 | J7: 46002 | K7: RA-01 | L7: 92.4 | M7: 92.9 | N7: =M7-L7 -> 0.5
A8: 2 | B8: F1 | C8: 2 | D8: 1.7 | E8: 1.7 | F8: 0.05 | G8: =+PRODUCT(C8:F8) -> 0.289 | J8: 46002 | K8: RA-01 | N8: =M8-L8 -> 0
A9: 3 | B9: Pump room Deductions | C9: -1 | D9: 78.62 | F9: =0.5-0.2 -> 0.3 | G9: =+PRODUCT(C9:F9) -> -23.586 | J9: 46002 | K9: RA-01 | N9: =M9-L9 -> 0
A10: 4 | B10: Drain pit slab | C10: -1 | D10: 6.276 | F10: 0.5 | G10: =+PRODUCT(C10:F10) -> -3.138 | J10: 46002 | K10: RA-01 | N10: =M10-L10 -> 0
B11: Collection Sump | N11: =M11-L11 -> 0
A12: 5 | B12: Drain pit raft | C12: 1 | D12: 11.494 | F12: =+N12 -> 0.5 | G12: =+PRODUCT(C12:F12) -> 5.747 | K12: RA-01 | L12: 90.3 | M12: 90.8 | N12: =M12-L12 -> 0.5
C15: Cumulative Quantity | G15: =SUM(G7:G14) -> 170.316 | H15: Cum
C16: Prev. Billed Quantity | G16: =+'Abstract-QS'!G15 -> 0 | H16: Cum
C17: Present Bill Quantity | G17: =G15-G16 -> 170.316 | H17: Cum

Sheet STP Raft-S
A1: PROJECT : TECHRIDGE- P3 | B1: : The Quiet Side
A2: M/s. Divyashree Infrastructure Projects Pvt Ltd
A3: Subject: STP Raft Shuttering Joint Measurement Details
A4: ='Abstract-QS'!C7 -> : RA-01
A5: Sl No | B5: Description | C5: Nos | D5: L | E5: B | F5: D | G5: Qty in Sqm | H5: Grid | I5: Pourcard No | J5: Pourcard Date | K5: RA No. | L5: Raft Bottom Level | M5: Raft Top Level | N5: Depth
B6: STP
A7: 1 | B7: STP Raft | C7: 1 | D7: 83.114 | F7: =+N7 -> 0.5 | G7: =+PRODUCT(C7:F7) -> 41.557 | J7: 46002 | K7: RA-01 | L7: 92.4 | M7: 92.9 | N7: =M7-L7 -> 0.5
A8: 2 | B8: F1 | C8: 2 | D8: 1.7 | E8: 1.7 | F8: 0.5 | G8: =C8*(D8+E8+D8+E8)*F8 -> 6.8 | J8: 46002 | K8: RA-01 | N8: =M8-L8 -> 0
B9: Collection Sump | G9: =(D9+E9+D9+E9)*F9 -> 0 | N9: =M9-L9 -> 0
A10: 3 | B10: Collection Sump Raft | C10: 1 | D10: 14.199 | F10: 0.5 | G10: =+PRODUCT(C10:F10) -> 7.0995 | K10: RA-01 | L10: 90.3 | M10: 90.8 | N10: =M10-L10 -> 0.5
G11: =+PRODUCT(C11:F11) -> 0 | N11: =M11-L11 -> 0
N12: =M12-L12 -> 0
N13: =M13-L13 -> 0
C14: Cumulative Quantity | G14: =SUM(G7:G11) -> 55.4565 | H14: Sqm
C15: Prev. Billed Quantity | G15: =+'Abstract-QS'!G15 -> 0 | H15: Sqm
C16: Present Bill Quantity | G16: =G14-G15 -> 55.4565 | H16: Sqm

Sheet STP Wall-C
A1: PROJECT : TECHRIDGE- P3 | B1: : The Quiet Side
A2: M/s. Divyashree Infrastructure Projects Pvt Ltd
A3: Subject: STP Wall Concrete Joint Measurement Details
A4: ='Abstract-QS'!C7 -> : RA-01
A5: Sl No | B5: Description | C5: Nos | D5: L | E5: B | F5: D | G5: Qty in Cum | H5: Grid | I5: Pourcard No | J5: Pourcard Date | K5: RA No. | L5: Top Avg.Level | M5: Bottom Avg. Level
B6: Drain pit
A7: 1 | B7: Collection Sump Wall | C7: 1 | D7: 1.75 | E7: 0.25 | F7: =L7-M7 -> 1.5 | G7: =+PRODUCT(C7:F7) -> 0.65625 | K7: RA-01 | L7: 92.3 | M7: 90.8
A8: 2 | B8: Collection Sump Wall | C8: 1 | D8: 3.1 | E8: 0.25 | F8: =L8-M8 -> 1.5 | G8: =+PRODUCT(C8:F8) -> 1.1625 | K8: RA-01 | L8: 92.3 | M8: 90.8
A9: 3 | B9: Collection Sump Wall | C9: 1 | D9: 1.75 | E9: 0.35 | F9: =L9-M9 -> 1.5 | G9: =+PRODUCT(C9:F9) -> 0.91875 | K9: RA-01 | L9: 92.3 | M9: 90.8
A10: 4 | B10: Collection Sump Wall | C10: 1 | D10: 3.1 | E10: 0.3 | F10: =L10-M10 -> 1.5 | G10: =+PRODUCT(C10:F10) -> 1.395 | K10: RA-01 | L10: 92.3 | M10: 90.8
F11: =L11-M11 -> 0 | G11: =+PRODUCT(C11:F11) -> 0
C13: Cumulative Quantity | G13: =SUM(G6:G12) -> 4.1325 | H13: Cum
C14: Prev. Billed Quantity | G14: =+'Abstract-QS'!G15 -> 0 | H14: Cum
C15: Present Bill Quantity | G15: =G13-G14 -> 4.1325 | H15: Cum

Sheet STP Wall-S
A1: PROJECT : TECHRIDGE- P3 | B1: : The Quiet Side
A2: M/s. Divyashree Infrastructure Projects Pvt Ltd
A3: Subject: STP Wall Shuttering Joint Measurement Details
A4: ='Abstract-QS'!C7 -> : RA-01
A5: Sl No | B5: Description | C5: Nos | D5: L | E5: B | F5: D | G5: Qty in Sqm | H5: Grid | I5: Pourcard No | J5: Pourcard Date | K5: RA No. | L5: Top Avg.Level | M5: Bottom Avg. Level
B6: Drain pit
A7: 1 | B7: Collection Sump Wall | C7: 1 | D7: 1.75 | E7: 0.25 | F7: =L7-M7 -> 1.5 | G7: =(D7+E7+D7+E7)*C7*F7 -> 6 | K7: RA-01 | L7: 92.3 | M7: 90.8
A8: 2 | B8: Collection Sump Wall | C8: 1 | D8: 3.1 | E8: 0.25 | F8: =L8-M8 -> 1.5 | G8: =(D8+E8+D8+E8)*C8*F8 -> 10.05 | K8: RA-01 | L8: 92.3 | M8: 90.8
A9: 3 | B9: Collection Sump Wall | C9: 1 | D9: 1.75 | E9: 0.35 | F9: =L9-M9 -> 1.5 | G9: =(D9+E9+D9+E9)*C9*F9 -> 6.3 | K9: RA-01 | L9: 92.3 | M9: 90.8
A10: 4 | B10: Collection Sump Wall | C10: 1 | D10: 3.1 | E10: 0.3 | F10: =L10-M10 -> 1.5 | G10: =(D10+E10+D10+E10)*C10*F10 -> 10.2 | K10: RA-01 | L10: 92.3 | M10: 90.8
F11: =L11-M11 -> 0 | G11: =+PRODUCT(C11:F11) -> 0
C13: Cumulative Quantity | G13: =SUM(G6:G12) -> 32.55 | H13: Sqm
C14: Prev. Billed Quantity | G14: =+'Abstract-QS'!G15 -> 0 | H14: Sqm
C15: Present Bill Quantity | G15: =G13-G14 -> 32.55 | H15: Sqm

Sheet Penetron-Admixture
A1: PROJECT : TECHRIDGE- P3 | B1: : The Quiet Side
A2: M/s. Divyashree Infrastructure Projects Pvt Ltd
A3: Subject: Penetron Admixture Joint Measurement Details
A4: ='Abstract-QS'!C7 -> : RA-01
A5: Sl No | B5: Description | C5: Nos | D5: L | E5: B | F5: D | G5: Qty in Cum | H5: Grid | I5: Pourcard No | J5: Pourcard Date | K5: RA No. | L5: Raft Bottom Level | M5: Raft Top Level | N5: Depth
A6: 1 | B6: West Retaining wall Raft | C6: 1 | D6: 18.3 | E6: 2.95 | F6: =+N6 -> 0.7 | G6: =+PRODUCT(C6:F6) -> 37.7895 | J6: 45989 | K6: RA-01 | L6: 95.875 | M6: 96.575 | N6: =M6-L6 -> 0.7
A7: 2 | B7: West Retaining wall Raft | C7: 0 | D7: 18.4 | E7: 2.95 | F7: =+N7 -> 0.03 | G7: =+PRODUCT(C7:F7) -> 0 | J7: 45989 | K7: RA-01 | L7: =M7-0.03 -> 95.85 | M7: 95.88 | N7: =M7-L7 -> 0.03
A8: 3 | B8: West Retaining wall Raft | C8: 1 | D8: 24.8 | E8: 2.95 | F8: =+N8 -> 0.7 | G8: =+PRODUCT(C8:F8) -> 51.212 | J8: 45993 | K8: RA-01 | L8: 95.875 | M8: 96.575 | N8: =M8-L8 -> 0.7
A9: 4 | B9: West Retaining wall Raft | C9: 0 | D9: 24.8 | E9: 2.95 | F9: =+N9 -> 0.03 | G9: =+PRODUCT(C9:F9) -> 0 | J9: 45993 | K9: RA-01 | L9: =M9-0.03 -> 95.85 | M9: 95.88 | N9: =M9-L9 -> 0.03
B10: STP
A11: 5 | B11: STP Raft | C11: 1 | D11: 382.008 | F11: 0.5 | G11: =+PRODUCT(C11:F11) -> 191.004 | K11: RA-01
A12: 6 | B12: F1 | C12: 2 | D12: 1.7 | E12: 1.7 | F12: 0.55 | G12: =+PRODUCT(C12:F12) -> 3.179 | K12: RA-01
A13: 7 | B13: Pump room deduction | C13: -1 | D13: 78.62 | F13: 0.3 | G13: =+PRODUCT(C13:F13) -> -23.586 | K13: RA-01
A14: 8 | B14: Drain pit deduction | C14: -1 | D14: 3.1 | E14: 1.2 | F14: 0.5 | G14: =+PRODUCT(C14:F14) -> -1.86 | K14: RA-01
B15: Collection Sump
A16: 9 | B16: Collection Sump Raft | C16: 1 | D16: 4.6 | E16: 2.5 | F16: =+N16 -> 0.5 | G16: =+PRODUCT(C16:F16) -> 5.75 | K16: RA-01 | L16: 90.3 | M16: 90.8 | N16: =M16-L16 -> 0.5
A17: 10 | B17: Collection Sump Wall | C17: 1 | D17: 1.75 | E17: 0.25 | F17: =+N17 -> 1.95 | G17: =+PRODUCT(C17:F17) -> 0.853125 | K17: RA-01 | L17: 90.8 | M17: 92.75 | N17: =M17-L17 -> 1.95
A18: 11 | B18: Collection Sump Wall | C18: 1 | D18: 3.1 | E18: 0.25 | F18: =+N18 -> 1.95 | G18: =+PRODUCT(C18:F18) -> 1.51125 | K18: RA-01 | L18: 90.8 | M18: 92.75 | N18: =M18-L18 -> 1.95
A19: 12 | B19: Collection Sump Wall | C19: 1 | D19: 1.75 | E19: 0.35 | F19: =+N19 -> 1.95 | G19: =+PRODUCT(C19:F19) -> 1.194375 | K19: RA-01 | L19: 90.8 | M19: 92.75 | N19: =M19-L19 -> 1.95
A20: 13 | B20: Collection Sump Wall | C20: 1 | D20: 3.1 | E20: 0.3 | F20: =+N20 -> 1.95 | G20: =+PRODUCT(C20:F20) -> 1.8135 | K20: RA-01 | L20: 90.8 | M20: 92.75 | N20: =M20-L20 -> 1.95
A21: 14 | G21: =+PRODUCT(C21:F21) -> 0
G22: =+PRODUCT(C22:F22) -> 0
C25: Cumulative Quantity | G25: =SUM(G6:G22) -> 268.86075 | H25: Cum
C26: Prev. Billed Quantity | G26: =+'Abstract-QS'!G15 -> 0 | H26: Cum
C27: Present Bill Quantity | G27: =G25-G26 -> 268.86075 | H27: Cum

Sheet Steel Abstract
A1: PROJECT : TECHRIDGE- P3 | B1: : The Quiet Side
A2: M/s. Divyashree Infrastructure Projects Pvt Ltd
A3: Subject: Reinforcement Joint Measurement Details
A4: =+'Abstract-QS'!C7 -> : RA-01
A5: SL.No | B5: Description | C5: Unit | D5: Dia 8mm | E5: Dia 10mm | F5: Dia 12mm | G5: Dia 16mm | H5: Dia 20mm | I5: Dia 25mm | J5: Dia 32mm | K5: Total | M5: Prev Qty | O5: This Bill Qty
A6: 1 | B6: Retaining Wall
B7: Raft | C7: MT | D7: 0 | E7: 0.9989847 | F7: 2.1624036 | G7: 3.110072 | H7: 0 | I7: 0 | J7: 0 | K7: =ROUND((SUM(D7:J7)),3) -> 6.271 | M7: 0 | O7: =+K7-M7 -> 6.271
K8: =ROUND((SUM(D8:J8)),3) -> 0 | O8: =+K8-M8 -> 0
A9: 2 | B9: STP | K9: =ROUND((SUM(D9:J9)),3) -> 0 | O9: =+K9-M9 -> 0
B10: Raft | C10: MT | D10: 0.0255328 | E10: 3.2184262 | F10: 9.8944989 | G10: 6.40295 | H10: 7.8604812 | K10: =ROUND((SUM(D10:J10)),3) -> 27.402 | M10: 0 | O10: =+K10-M10 -> 27.402
K11: =ROUND((SUM(D11:J11)),3) -> 0 | O11: =+K11-M11 -> 0
B13: Cumulative Qty | D13: =ROUND(SUM(D7:D12),3) -> 0.026 | E13: =ROUND(SUM(E7:E12),3) -> 4.217 | F13: =ROUND(SUM(F7:F12),3) -> 12.057 | G13: =ROUND(SUM(G7:G12),3) -> 9.513 | H13: =ROUND(SUM(H7:H12),3) -> 7.86 | I13: =ROUND(SUM(I7:I12),3) -> 0 | J13: =ROUND(SUM(J7:J12),3) -> 0 | K13: =ROUND(SUM(K7:K12),3) -> 33.673 | M13: =ROUND(SUM(M6:M12),3) -> 0 | O13: =ROUND(SUM(O6:O12),3) -> 33.673
B14: Prev Qty | K14: =SUM(D14:J14) -> 0 | L14: =+'Abstract-QS'!G19 -> 0 | M14: =SUM(M8:M13) -> 0
B15: This Bill Qty | D15: =+D13-D14 -> 0.026 | E15: =+E13-E14 -> 4.217 | F15: =+F13-F14 -> 12.057 | G15: =+G13-G14 -> 9.513 | H15: =+H13-H14 -> 7.86 | I15: =+I13-I14 -> 0 | J15: =+J13-J14 -> 0 | K15: =+K13-K14 -> 33.673

Sheet RMC Basic Price Escalation
A1: PROJECT : TECHRIDGE- P3
A2: M/s. Divyashree Infrastructure Projects Pvt Ltd
A3: Subject: RMC Basic Price Escalation Statement
A4: =+'Abstract-QS'!C7 -> : RA-01 | G4: =SUBTOTAL(9,G6:G51) -> 374.5 | H4: =SUBTOTAL(9,H6:H51) -> 355.8865 | I4: =G4-H4 -> 18.6135
A5: Sl. No. | B5: Name of Suppliers | C5: INVOICE NO | D5: INVOICE DATE | E5: Unit | F5: Grade of Concrete | G5: Received Quantity in Cum | H5: Consumed Quantity in Cum | I5: Base Rate in Rs. (A) | J5: Approved Rate in Rs. (B) | K5: Purchase Rate in Rs. (C) | L5: Differ. in Rate (App. ) ( Rs. ) | M5: Minimum of B and C | N5: Differ. in Rate (Purch. ) ( Rs. ) | O5: Total Basic rate variation amount | P5: Remarks
A7: 1 | B7: SCP Concrete | C7: 02074/2025-2026 | D7: 45971 | E7: Cum | F7: 10 | G7: 7 | H7: 7 | I7: =(IF(F7=10,"3410"))+(IF(F7=30,"3920")) -> 3410 | J7: 3432.2034 | K7: 3432.2034 | L7: =+K7-I7 -> 22.20339 | M7: =MIN(J7:K7) -> 3432.2034 | N7: =+M7-I7 -> 22.20339 | O7: =+N7*H7 -> 155.42373 | Q7: =G7-H7 -> 0
A8: 2 | B8: SCP Concrete | C8: 02072/2025-2026 | D8: 45971 | E8: Cum | F8: 10 | G8: 7 | H8: 7 | I8: =(IF(F8=10,"3410"))+(IF(F8=30,"3920")) -> 3410 | J8: 3432.2034 | K8: 3432.2034 | L8: =+K8-I8 -> 22.20339 | M8: =MIN(J8:K8) -> 3432.2034 | N8: =+M8-I8 -> 22.20339 | O8: =+N8*H8 -> 155.42373 | Q8: =G8-H8 -> 0
A9: 3 | B9: SCP Concrete | C9: 02196/2025-2026 | D9: 45982 | E9: Cum | F9: 10 | G9: 7 | H9: 7 | I9: =(IF(F9=10,"3410"))+(IF(F9=30,"3920")) -> 3410 | J9: 3432.2034 | K9: 3432.2034 | L9: =+K9-I9 -> 22.20339 | M9: =MIN(J9:K9) -> 3432.2034 | N9: =+M9-I9 -> 22.20339 | O9: =+N9*H9 -> 155.42373 | Q9: =G9-H9 -> 0
A10: 4 | B10: SCP Concrete | C10: 02198/2025-2026 | D10: 45982 | E10: Cum | F10: 10 | G10: 10 | H10: 10 | I10: =(IF(F10=10,"3410"))+(IF(F10=30,"3920")) -> 3410 | J10: 3432.2034 | K10: 3432.2034 | L10: =+K10-I10 -> 22.20339 | M10: =MIN(J10:K10) -> 3432.2034 | N10: =+M10-I10 -> 22.20339 | O10: =+N10*H10 -> 222.0339 | Q10: =G10-H10 -> 0
A11: 5 | B11: SCP Concrete | C11: 02199/2025-2026 | D11: 45982 | E11: Cum | F11: 10 | G11: 8 | H11: 8 | I11: =(IF(F11=10,"3410"))+(IF(F11=30,"3920")) -> 3410 | J11: 3432.2034 | K11: 3432.2034 | L11: =+K11-I11 -> 22.20339 | M11: =MIN(J11:K11) -> 3432.2034 | N11: =+M11-I11 -> 22.20339 | O11: =+N11*H11 -> 177.62712 | Q11: =G11-H11 -> 0
A12: 6 | B12: SCP Concrete | C12: 02210/2025-2026 | D12: 45983 | E12: Cum | F12: 10 | G12: 5 | H12: 5 | I12: =(IF(F12=10,"3410"))+(IF(F12=30,"3920")) -> 3410 | J12: 3432.2034 | K12: 3432.2034 | L12: =+K12-I12 -> 22.20339 | M12: =MIN(J12:K12) -> 3432.2034 | N12: =+M12-I12 -> 22.20339 | O12: =+N12*H12 -> 111.01695 | Q12: =G12-H12 -> 0
A13: 7 | B13: SCP Concrete | C13: 02204/2025-2026 | D13: 45983 | E13: Cum | F13: 10 | G13: 10 | H13: 10 | I13: =(IF(F13=10,"3410"))+(IF(F13=30,"3920")) -> 3410 | J13: 3432.2034 | K13: 3432.2034 | L13: =+K13-I13 -> 22.20339 | M13: =MIN(J13:K13) -> 3432.2034 | N13: =+M13-I13 -> 22.20339 | O13: =+N13*H13 -> 222.0339 | Q13: =G13-H13 -> 0
A14: 8 | B14: SCP Concrete | C14: 02243/2025-2026 | D14: 45985 | E14: Cum | F14: 10 | G14: 4 | H14: 4 | I14: =(IF(F14=10,"3410"))+(IF(F14=30,"3920")) -> 3410 | J14: 3432.2034 | K14: 3432.2034 | L14: =+K14-I14 -> 22.20339 | M14: =MIN(J14:K14) -> 3432.2034 | N14: =+M14-I14 -> 22.20339 | O14: =+N14*H14 -> 88.813559 | Q14: =G14-H14 -> 0
A15: 9 | B15: SCP Concrete | C15: 02273/2025-2026 | D15: 45987 | E15: Cum | F15: 10 | G15: 6 | H15: 6 | I15: =(IF(F15=10,"3410"))+(IF(F15=30,"3920")) -> 3410 | J15: 3432.2034 | K15: 3432.2034 | L15: =+K15-I15 -> 22.20339 | M15: =MIN(J15:K15) -> 3432.2034 | N15: =+M15-I15 -> 22.20339 | O15: =+N15*H15 -> 133.22034 | Q15: =G15-H15 -> 0
A16: 10 | B16: SCP Concrete | C16: 02272/2025-2026 | D16: 45987 | E16: Cum | F16: 10 | G16: 6 | H16: 6 | I16: =(IF(F16=10,"3410"))+(IF(F16=30,"3920")) -> 3410 | J16: 3432.2034 | K16: 3432.2034 | L16: =+K16-I16 -> 22.20339 | M16: =MIN(J16:K16) -> 3432.2034 | N16: =+M16-I16 -> 22.20339 | O16: =+N16*H16 -> 133.22034 | Q16: =G16-H16 -> 0
A17: 11 | B17: SCP Concrete | C17: 02292/2025-2026 | D17: 45989 | E17: Cum | F17: 30 | G17: 10 | H17: 10 | I17: =(IF(F17=10,"3410"))+(IF(F17=30,"3920")) -> 3920 | J17: 4152.5424 | K17: 4152.5424 | L17: =+K17-I17 -> 232.54237 | M17: =MIN(J17:K17) -> 4152.5424 | N17: =+M17-I17 -> 232.54237 | O17: =+N17*H17 -> 2325.4237 | Q17: =G17-H17 -> 0
A18: 12 | B18: SCP Concrete | C18: 02295/2025-2026 | D18: 45989 | E18: Cum | F18: 30 | G18: 10 | H18: 10 | I18: =(IF(F18=10,"3410"))+(IF(F18=30,"3920")) -> 3920 | J18: 4152.5424 | K18: 4152.5424 | L18: =+K18-I18 -> 232.54237 | M18: =MIN(J18:K18) -> 4152.5424 | N18: =+M18-I18 -> 232.54237 | O18: =+N18*H18 -> 2325.4237 | Q18: =G18-H18 -> 0
... A28: 22 | B28: SCP Concrete | C28: 02394/2025/2026 | D28: 45995 | E28: Cum | F28: 30 | G28: 4 | H28: 4 | I28: =(IF(F28=10,"3410"))+(IF(F28=30,"3920")) -> 3920 | J28: 4152.5424 | K28: 4152.5424 | L28: =+K28-I28 -> 232.54237 | M28: =MIN(J28:K28) -> 4152.5424 | N28: =+M28-I28 -> 232.54237 | O28: =+N28*H28 -> 930.16949 | Q28: =G28-H28 -> 0
A29: 23 | B29: SCP Concrete | C29: 02438/2025-2026 | D29: 45997 | E29: Cum | F29: 10 | G29: 7.5 | H29: ='PCC-C'!G20-70 -> 17.8865 | I29: =(IF(F29=10,"3410"))+(IF(F29=30,"3920")) -> 3410 | J29: 3432.2034 | K29: 3432.2034 | L29: =+K29-I29 -> 22.20339 | M29: =MIN(J29:K29) -> 3432.2034 | N29: =+M29-I29 -> 22.20339 | O29: =+N29*H29 -> 397.14093 | Q29: =G29-H29 -> -10.3865
A30: 24 | B30: SCP Concrete | C30: 02465/2025-2026 | D30: 46002 | E30: Cum | F30: 10 | G30: 10 | H30: 6 | I30: =(IF(F30=10,"3410"))+(IF(F30=30,"3920")) -> 3410 | J30: 4152.5424 | K30: 4152.5424 | L30: =+K30-I30 -> 742.54237 | M30: =MIN(J30:K30) -> 4152.5424 | N30: =+M30-I30 -> 742.54237 | O30: =+N30*H30 -> 4455.2542 | Q30: =G30-H30 -> 4
A31: 25 | B31: SCP Concrete | C31: 02466/2025-2026 | D31: 46002 | E31: Cum | F31: 30 | G31: 10 | H31: 10 | I31: =(IF(F31=10,"3410"))+(IF(F31=30,"3920")) -> 3920 | J31: 4152.5424 | K31: 4152.5424 | L31: =+K31-I31 -> 232.54237 | M31: =MIN(J31:K31) -> 4152.5424 | N31: =+M31-I31 -> 232.54237 | O31: =+N31*H31 -> 2325.4237 | Q31: =G31-H31 -> 0
A32: 26 | B32: SCP Concrete | C32: 02467/2025-2026 | D32: 46002 | E32: Cum | F32: 30 | G32: 10 | H32: 10 | I32: =(IF(F32=10,"3410"))+(IF(F32=30,"3920")) -> 3920 | J32: 4152.5424 | K32: 4152.5424 | L32: =+K32-I32 -> 232.54237 | M32: =MIN(J32:K32) -> 4152.5424 | N32: =+M32-I32 -> 232.54237 | O32: =+N32*H32 -> 2325.4237 | Q32: =G32-H32 -> 0
A33: 27 | B33: SCP Concrete | C33: 02468/2025-2026 | D33: 46002 | E33: Cum | F33: 30 | G33: 10 | H33: 10 | I33: =(IF(F33=10,"3410"))+(IF(F33=30,"3920")) -> 3920 | J33: 4152.5424 | K33: 4152.5424 | L33: =+K33-I33 -> 232.54237 | M33: =MIN(J33:K33) -> 4152.5424 | N33: =+M33-I33 -> 232.54237 | O33: =+N33*H33 -> 2325.4237 | Q33: =G33-H33 -> 0
A34: 28 | B34: SCP Concrete | C34: 02469/2025-2026 | D34: 46002 | E34: Cum | F34: 30 | G34: 10 | H34: 10 | I34: =(IF(F34=10,"3410"))+(IF(F34=30,"3920")) -> 3920 | J34: 4152.5424 | K34: 4152.5424 | L34: =+K34-I34 -> 232.54237 | M34: =MIN(J34:K34) -> 4152.5424 | N34: =+M34-I34 -> 232.54237 | O34: =+N34*H34 -> 2325.4237 | Q34: =G34-H34 -> 0
A35: 29 | B35: SCP Concrete | C35: 02470/2025-2026 | D35: 46002 | E35: Cum | F35: 30 | G35: 10 | H35: 10 | I35: =(IF(F35=10,"3410"))+(IF(F35=30,"3920")) -> 3920 | J35: 4152.5424 | K35: 4152.5424 | L35: =+K35-I35 -> 232.54237 | M35: =MIN(J35:K35) -> 4152.5424 | N35: =+M35-I35 -> 232.54237 | O35: =+N35*H35 -> 2325.4237 | Q35: =G35-H35 -> 0
A36: 30 | B36: SCP Concrete | C36: 02471/2025-2026 | D36: 46002 | E36: Cum | F36: 30 | G36: 10 | H36: 10 | I36: =(IF(F36=10,"3410"))+(IF(F36=30,"3920")) -> 3920 | J36: 4152.5424 | K36: 4152.5424 | L36: =+K36-I36 -> 232.54237 | M36: =MIN(J36:K36) -> 4152.5424 | N36: =+M36-I36 -> 232.54237 | O36: =+N36*H36 -> 2325.4237 | Q36: =G36-H36 -> 0
A37: 31 | B37: SCP Concrete | C37: 02473/2025-2026 | D37: 46002 | E37: Cum | F37: 30 | G37: 10 | H37: 10 | I37: =(IF(F37=10,"3410"))+(IF(F37=30,"3920")) -> 3920 | J37: 4152.5424 | K37: 4152.5424 | L37: =+K37-I37 -> 232.54237 | M37: =MIN(J37:K37) -> 4152.5424 | N37: =+M37-I37 -> 232.54237 | O37: =+N37*H37 -> 2325.4237 | Q37: =G37-H37 -> 0
A38: 32 | B38: SCP Concrete | C38: 02474/2025-2026 | D38: 46002 | E38: Cum | F38: 30 | G38: 10 | H38: 10 | I38: =(IF(F38=10,"3410"))+(IF(F38=30,"3920")) -> 3920 | J38: 4152.5424 | K38: 4152.5424 | L38: =+K38-I38 -> 232.54237 | M38: =MIN(J38:K38) -> 4152.5424 | N38: =+M38-I38 -> 232.54237 | O38: =+N38*H38 -> 2325.4237 | Q38: =G38-H38 -> 0
A39: 33 | B39: SCP Concrete | C39: 02478/2025-2026 | D39: 46002 | E39: Cum | F39: 30 | G39: 10 | H39: 10 | I39: =(IF(F39=10,"3410"))+(IF(F39=30,"3920")) -> 3920 | J39: 4152.5424 | K39: 4152.5424 | L39: =+K39-I39 -> 232.54237 | M39: =MIN(J39:K39) -> 4152.5424 | N39: =+M39-I39 -> 232.54237 | O39: =+N39*H39 -> 2325.4237 | Q39: =G39-H39 -> 0
A40: 34 | B40: SCP Concrete | C40: 02479/2025-2026 | D40: 46002 | E40: Cum | F40: 30 | G40: 10 | H40: 10 | I40: =(IF(F40=10,"3410"))+(IF(F40=30,"3920")) -> 3920 | J40: 4152.5424 | K40: 4152.5424 | L40: =+K40-I40 -> 232.54237 | M40: =MIN(J40:K40) -> 4152.5424 | N40: =+M40-I40 -> 232.54237 | O40: =+N40*H40 -> 2325.4237 | Q40: =G40-H40 -> 0
A41: 35 | B41: SCP Concrete | C41: 02480/2025-2026 | D41: 46002 | E41: Cum | F41: 30 | G41: 10 | H41: 10 | I41: =(IF(F41=10,"3410"))+(IF(F41=30,"3920")) -> 3920 | J41: 4152.5424 | K41: 4152.5424 | L41: =+K41-I41 -> 232.54237 | M41: =MIN(J41:K41) -> 4152.5424 | N41: =+M41-I41 -> 232.54237 | O41: =+N41*H41 -> 2325.4237 | Q41: =G41-H41 -> 0
... A49: 43 | B49: SCP Concrete | C49: 02510/2025-2026 | D49: 46003 | E49: Cum | F49: 10 | G49: 5 | H49: 0 | I49: =(IF(F49=10,"3410"))+(IF(F49=30,"3920")) -> 3410 | J49: 3432.2034 | K49: 3432.2034 | L49: =+K49-I49 -> 22.20339 | M49: =MIN(J49:K49) -> 3432.2034 | N49: =+M49-I49 -> 22.20339 | O49: =+N49*H49 -> 0 | Q49: =G49-H49 -> 5
A50: 44 | L50: =+K50-I50 -> 0 | M50: =MIN(J50:K50) -> 0 | N50: =+M50-I50 -> 0 | O50: =+N50*H50 -> 0 | Q50: =G50-H50 -> 0
B52: Grand Total | G52: =SUBTOTAL(9,G6:G51) -> 374.5 | H52: =SUBTOTAL(9,H6:H51) -> 355.8865 | K52: Cumulative Certified amount | O52: =SUM(O6:O51) -> 67332.734
K53: Amount certified till Previous bill | O53: 0
K54: Amount certified in Current bill | O54: =O52-O53 -> 67332.734

